Workbook

Sheet GE90TB7716236080100009-GEL
A1: Date | B1: Description | C1: Additional Information | D1: Paid Out | E1: Paid In | F1: Balance | G1: Type | H1: Document Date | I1: Document Number | J1: Partner's Account | K1: Partner's Name | L1: Partner's Tax Code | M1: Partner's Bank Code | N1: Partner's Bank | O1: Intermediary Bank Code | P1: Intermediary Bank | Q1: Charge Details | R1: Taxpayer Code | S1: Taxpayer Name | T1: Treasury Code | U1: Op. Code | V1: Additional Description | W1: Transaction ID
A2: 46113 | B2: ლაიფსთორი | C2: ბესარიონი ფაჩულია, 35001107730, TBCBGE22, GE31TB7024045064300028 | E2: 67 | F2: 10330.78 | G2: შემოსავალი | H2: 46113 | I2: 1774991775 | J2: GE31TB7024045064300028 | K2: ბესარიონი ფაჩულია, 35001107730 | L2: 35001107730 | M2: TBCBGE22 | N2: სს "თიბისი ბანკი" | R2: 35001107730 | S2: ბესარიონი ფაჩულია, 35001107730 | U2: GMB | W2: 19226691072
A3: 46113 | B3: ინვოისი 313349.113 | C3: შპს 'სოკარ ჯორჯია პეტროლეუმი', TBCBGE22, GE66TB0614336020100002 | D3: 259.2 | F3: 10071.58 | G3: გადარიცხვა თანხის გატანა | H3: 46113 | I3: 1775028368 | J3: GE66TB0614336020100002 | K3: შპს 'სოკარ ჯორჯია პეტროლეუმი' | L3: 202352514 | M3: TBCBGE22 | N3: სს "თიბისი ბანკი" | R3: 405357180 | S3: შპს დელივერერს, 405357180 | U3: GIB | W3: 19228960324
A4: 46113 | B4: მომსახურების ანაზღაურება | C4: ი/მ ოთარ კუპრეიშვილი, 42401042214, TBCBGE22, GE76TB7494745068100005 | E4: 235 | F4: 10306.58 | G4: შემოსავალი | H4: 46113 | I4: 1775063791 | J4: GE76TB7494745068100005 | K4: ი/მ ოთარ კუპრეიშვილი, 42401042214 | L4: 42401042214 | M4: TBCBGE22 | N4: სს "თიბისი ბანკი" | R4: 42401042214 | S4: ი/მ ოთარ კუპრეიშვილი, 42401042214 | U4: GMB | W4: 19238216238
A5: 46113 | B5: ძირითადი თანხის დაფარვა;შპს დელივერერს;7007162-14773527 | C5: ძირითადი თანხა - ბიზნეს სესხები, TBCBGE22, GE36TB0001201000001007 | D5: 752.01 | F5: 9554.57 | G5: სხვა ხარჯები | H5: 46113 | I5: 2271785 | J5: GE36TB0001201000001007 | K5: ძირითადი თანხა - ბიზნეს სესხები | M5: TBCBGE22 | N5: ს.ს. თიბისი ბანკი | U5: *LPPR | W5: 19239211470
A6: 46113 | B6: პროცენტის დაფარვა;შპს დელივერერს;7007162-14773527 | C6: დარიცხული პროცენტი - ბიზნეს სესხები, TBCBGE22, GE94TB0001201000102007 | D6: 389.54 | F6: 9165.03 | G6: სხვა ხარჯები | H6: 46113 | I6: 2271787 | J6: GE94TB0001201000102007 | K6: დარიცხული პროცენტი - ბიზნეს სესხები | M6: TBCBGE22 | N6: ს.ს. თიბისი ბანკი | U6: *LPIN | W6: 19239211474
A7: 46114 | B7: საკურიერო მომსახურება | C7: საქველმოქმედო ფონდი საკვების ბანკი, 404572440, TBCBGE22, GE36TB7791936080100009 | E7: 1668.52 | F7: 10833.55 | G7: შემოსავალი | H7: 46114 | I7: 1775113606 | J7: GE36TB7791936080100009 | K7: საქველმოქმედო ფონდი საკვების ბანკი, 404572440 | L7: 404572440 | M7: TBCBGE22 | N7: სს "თიბისი ბანკი" | R7: 404572440 | S7: საქველმოქმედო ფონდი საკვების ბანკი, 404572440 | U7: GIB | W7: 19240801189
A8: 46114 | B8: 9072 | C8: დავით სვირავა, 62003016407, TBCBGE22, GE89TB7657745063600036 | E8: 55 | F8: 10888.55 | G8: შემოსავალი | H8: 46114 | I8: 1775113900 | J8: GE89TB7657745063600036 | K8: დავით სვირავა, 62003016407 | L8: 62003016407 | M8: TBCBGE22 | N8: სს "თიბისი ბანკი" | R8: 62003016407 | S8: დავით სვირავა, 62003016407 | U8: GMB | W8: 19240847445
A9: 46114 | B9: 0841 | C9: ი/მ მიხეილ ლომჯარია, 01010000461, TBCBGE22, GE80TB7792445061600016 | E9: 100 | F9: 10988.55 | G9: შემოსავალი | H9: 46114 | I9: 1775115382 | J9: GE80TB7792445061600016 | K9: ი/მ მიხეილ ლომჯარია, 01010000461 | L9: 01010000461 | M9: TBCBGE22 | N9: სს "თიბისი ბანკი" | R9: 01010000461 | S9: ი/მ მიხეილ ლომჯარია, 01010000461 | U9: GMB | W9: 19241101353
A10: 46114 | B10: საკურიერო მომსახურება 01,03,2026-31,03,2026 ინვოისი 40 02,04,2026 | C10: შპს ეკობრენდს ჯორჯია, MIBGGE22, GE81PC0133600100036116 | E10: 2526.38 | F10: 13514.93 | G10: შემოსავალი | H10: 46114 | I10: 2 | J10: GE81PC0133600100036116 | K10: შპს ეკობრენდს ჯორჯია | L10: 202050564 | M10: MIBGGE22 | N10: სს "პროკრედიტ ბანკი, საქართველო" | R10: 202050564 | S10: შპს ეკობრენდს ჯორჯია | U10: BULK | W10: 19245309805
A11: 46114 | B11: ქეშების თანხა 21 მარტი - 31 მარტი | C11: შპს ლაიფ სთორი, TBCBGE22, GE38TB7826036080100014 | D11: 2510 | F11: 11004.93 | G11: გადარიცხვა თანხის გატანა | H11: 46114 | I11: 1775127914 | J11: GE38TB7826036080100014 | K11: შპს ლაიფ სთორი | L11: 438125574 | M11: TBCBGE22 | N11: სს "თიბისი ბანკი" | R11: 405357180 | S11: შპს დელივერერს, 405357180 | U11: GIB | W11: 19245323645
A12: 46114 | B12: ეა-85 4293405 | C12: შპს ალფაინ სფაისიზ, BAGAGE22, GE77BG0000000212886100 | E12: 460.2 | F12: 11465.13 | G12: შემოსავალი | H12: 46114 | I12: 2385 | J12: GE77BG0000000212886100 | K12: შპს ალფაინ სფაისიზ | L12: 405204639 | M12: BAGAGE22 | N12: სს "საქართველოს ბანკი" | R12: 405204639 | S12: შპს ალფაინ სფაისიზ | U12: BULK | V12: Ref 2385 | W12: 19247006331
A13: 46114 | B13: მომსახურების ანაზღაურება | C13: შპს სი ენ სი, BAGAGE22, GE64BG0000000541143452 | E13: 103.25 | F13: 11568.38 | G13: შემოსავალი | H13: 46114 | I13: 125 | J13: GE64BG0000000541143452 | K13: შპს სი ენ სი | L13: 405096435 | M13: BAGAGE22 | N13: სს "საქართველოს ბანკი" | R13: 405096435 | S13: შპს სი ენ სი | U13: BULK | V13: Ref 0125 | W13: 19247037259
A14: 46114 | B14: საკურიერო მომსახურება ინვ 37 | C14: შპს ფილუეტ ჯორჯია, 404388783, TBCBGE22, GE58TB7135636020100001 | E14: 1359.95 | F14: 12928.33 | G14: შემოსავალი | H14: 46114 | I14: 1775128455 | J14: GE58TB7135636020100001 | K14: შპს ფილუეტ ჯორჯია, 404388783 | L14: 404388783 | M14: TBCBGE22 | N14: სს "თიბისი ბანკი" | R14: 404388783 | S14: შპს ფილუეტ ჯორჯია, 404388783 | U14: GIB | W14: 19247153753
A15: 46114 | B15: დელივერი | C15: შპს ორგანიკა, 405172316, TBCBGE22, GE26TB7345536080100005 | E15: 1677.96 | F15: 14606.29 | G15: შემოსავალი | H15: 46114 | I15: 1775141656 | J15: GE26TB7345536080100005 | K15: შპს ორგანიკა, 405172316 | L15: 405172316 | M15: TBCBGE22 | N15: სს "თიბისი ბანკი" | R15: 405172316 | S15: შპს ორგანიკა, 405172316 | U15: GMB | W15: 19249519887
A16: 46114 | B16: 0197 | C16: დავით სვირავა, 62003016407, TBCBGE22, GE89TB7657745063600036 | E16: 100 | F16: 14706.29 | G16: შემოსავალი | H16: 46114 | I16: 1775156085 | J16: GE89TB7657745063600036 | K16: დავით სვირავა, 62003016407 | L16: 62003016407 | M16: TBCBGE22 | N16: სს "თიბისი ბანკი" | R16: 62003016407 | S16: დავით სვირავა, 62003016407 | U16: GMB | W16: 19251465361
A17: 46114 | B17: 9813 | C17: დავით სვირავა, 62003016407, TBCBGE22, GE89TB7657745063600036 | E17: 64 | F17: 14770.29 | G17: შემოსავალი | H17: 46114 | I17: 1775156439 | J17: GE89TB7657745063600036 | K17: დავით სვირავა, 62003016407 | L17: 62003016407 | M17: TBCBGE22 | N17: სს "თიბისი ბანკი" | R17: 62003016407 | S17: დავით სვირავა, 62003016407 | U17: GMB | W17: 19251485999
A18: 46115 | B18: მარტის თვის საკურიერო მომსახურება | C18: შპს რითეილ ბიზნეს გრუპ, BAGAGE22, GE34BG0000000039117000 | E18: 230.1 | F18: 15000.39 | G18: შემოსავალი | H18: 46114 | I18: 30001 | J18: GE34BG0000000039117000 | K18: შპს რითეილ ბიზნეს გრუპ | L18: 205268529 | M18: BAGAGE22 | N18: სს "საქართველოს ბანკი" | R18: 205268529 | S18: შპს რითეილ ბიზნეს გრუპ | U18: BULK | V18: Ref 30001 | W18: 19252669005
A19: 46115 | B19: მარტის თვის საკურიერო მომსახურება | C19: შპს ვიგრუპ, BAGAGE22, GE05BG0000000161605727 | E19: 268.45 | F19: 15268.84 | G19: შემოსავალი | H19: 46114 | I19: 28362 | J19: GE05BG0000000161605727 | K19: შპს ვიგრუპ | L19: 405278284 | M19: BAGAGE22 | N19: სს "საქართველოს ბანკი" | R19: 405278284 | S19: შპს ვიგრუპ | U19: BULK | V19: Ref 28362 | W19: 19252678725
A20: 46115 | B20: მომსახურების ანაზღაურება | C20: შპს სიო ეკოთრეიდი, BAGAGE22, GE97BG0000000609061094 | E20: 241.31 | F20: 15510.15 | G20: შემოსავალი | H20: 46115 | I20: 221 | J20: GE97BG0000000609061094 | K20: შპს სიო ეკოთრეიდი | L20: 402340196 | M20: BAGAGE22 | N20: სს "საქართველოს ბანკი" | R20: 402340196 | S20: შპს სიო ეკოთრეიდი | U20: BULK | V20: Ref 0221 | W20: 19252690671
A21: 46115 | B21: INVOICE 1 DATE: 02.04.2026 | C21: შპს პრაიმ რითეილ გრუპ, 405118894, TBCBGE22, GE71TB7868136020100002 | E21: 24.78 | F21: 15534.93 | G21: შემოსავალი | H21: 46115 | I21: 1775207364 | J21: GE71TB7868136020100002 | K21: შპს პრაიმ რითეილ გრუპ, 405118894 | L21: 405118894 | M21: TBCBGE22 | N21: სს "თიბისი ბანკი" | R21: 405118894 | S21: შპს პრაიმ რითეილ გრუპ, 405118894 | U21: GIB | W21: 19255437695
A22: 46115 | B22: ინვოისი 313349.114 | C22: შპს 'სოკარ ჯორჯია პეტროლეუმი', TBCBGE22, GE66TB0614336020100002 | D22: 267.2 | F22: 15267.73 | G22: გადარიცხვა თანხის გატანა | H22: 46115 | I22: 1775207512 | J22: GE66TB0614336020100002 | K22: შპს 'სოკარ ჯორჯია პეტროლეუმი' | L22: 202352514 | M22: TBCBGE22 | N22: სს "თიბისი ბანკი" | R22: 405357180 | S22: შპს დელივერერს, 405357180 | U22: GIB | W22: 19256059575
A23: 46115 | B23: INVOICE 32 | C23: შპს კაფსულები, 405340082, TBCBGE22, GE09TB7830236020100006 | E23: 164.61 | F23: 15432.34 | G23: შემოსავალი | H23: 46115 | I23: 8870019 | J23: GE09TB7830236020100006 | K23: შპს კაფსულები, 405340082 | L23: 405340082 | M23: TBCBGE22 | N23: სს "თიბისი ბანკი" | R23: 405340082 | S23: შპს კაფსულები, 405340082 | U23: GIB | W23: 19258892499
A24: 46115 | B24: INVOICE 42 | C24: შპს ტუტტო, 429328104, TBCBGE22, GE73TB7361436080100013 | E24: 394.12 | F24: 15826.46 | G24: შემოსავალი | H24: 46115 | I24: 1775215590 | J24: GE73TB7361436080100013 | K24: შპს ტუტტო, 429328104 | L24: 429328104 | M24: TBCBGE22 | N24: სს "თიბისი ბანკი" | R24: 429328104 | S24: შპს ტუტტო, 429328104 | U24: GIB | W24: 19258910855
A25: 46115 | B25: DELIVERERS N 17 | C25: შპს ალპი, 405292776, TBCBGE22, GE42TB7696236020100001 | E25: 521.56 | F25: 16348.02 | G25: შემოსავალი | H25: 46115 | I25: 1775215829 | J25: GE42TB7696236020100001 | K25: შპს ალპი, 405292776 | L25: 405292776 | M25: TBCBGE22 | N25: სს "თიბისი ბანკი" | R25: 405292776 | S25: შპს ალპი, 405292776 | U25: GIB | W25: 19259015015
A26: 46115 | B26: 0544 | C26: ი/მ გიორგი მეტრეველი, 01401103956, TBCBGE22, GE88TB7774945064300063 | E26: 40 | F26: 16388.02 | G26: შემოსავალი | H26: 46115 | I26: 1775227064 | J26: GE88TB7774945064300063 | K26: ი/მ გიორგი მეტრეველი, 01401103956 | L26: 01401103956 | M26: TBCBGE22 | N26: სს "თიბისი ბანკი" | R26: 01401103956 | S26: ი/მ გიორგი მეტრეველი, 01401103956 | U26: GMB | W26: 19262188405
A27: 46115 | B27: 0513 | C27: დავით სვირავა, 62003016407, TBCBGE22, GE89TB7657745063600036 | E27: 149 | F27: 16537.02 | G27: შემოსავალი | H27: 46115 | I27: 1775241585 | J27: GE89TB7657745063600036 | K27: დავით სვირავა, 62003016407 | L27: 62003016407 | M27: TBCBGE22 | N27: სს "თიბისი ბანკი" | R27: 62003016407 | S27: დავით სვირავა, 62003016407 | U27: GMB | W27: 19263839607
A28: 46115 | B28: 0515 | C28: ი/მ მიხეილ ლომჯარია, 01010000461, TBCBGE22, GE80TB7792445061600016 | E28: 64 | F28: 16601.02 | G28: შემოსავალი | H28: 46115 | I28: 1775245795 | J28: GE80TB7792445061600016 | K28: ი/მ მიხეილ ლომჯარია, 01010000461 | L28: 01010000461 | M28: TBCBGE22 | N28: სს "თიბისი ბანკი" | R28: 01010000461 | S28: ი/მ მიხეილ ლომჯარია, 01010000461 | U28: GMB | W28: 19264068184
A29: 46116 | B29: 0549 | C29: დავით სვირავა, 62003016407, TBCBGE22, GE89TB7657745063600036 | E29: 85 | F29: 16686.02 | G29: შემოსავალი | H29: 46116 | I29: 1775284062 | J29: GE89TB7657745063600036 | K29: დავით სვირავა, 62003016407 | L29: 62003016407 | M29: TBCBGE22 | N29: სს "თიბისი ბანკი" | R29: 62003016407 | S29: დავით სვირავა, 62003016407 | U29: GMB | W29: 19265462321
A30: 46116 | B30: მომსახურების ანაზღაურება | C30: ი/მ ოთარ კუპრეიშვილი, 42401042214, TBCBGE22, GE76TB7494745068100005 | E30: 64 | F30: 16750.02 | G30: შემოსავალი | H30: 46116 | I30: 1775325771 | J30: GE76TB7494745068100005 | K30: ი/მ ოთარ კუპრეიშვილი, 42401042214 | L30: 42401042214 | M30: TBCBGE22 | N30: სს "თიბისი ბანკი" | R30: 42401042214 | S30: ი/მ ოთარ კუპრეიშვილი, 42401042214 | U30: GMB | W30: 19275006355
A31: 46118 | B31: მარტის საკურიერო მომსახურება | C31: შპს კოსმო, 427736355, TBCBGE22, GE82TB7695836080100009 | E31: 1274.4 | F31: 18024.42 | G31: შემოსავალი | H31: 46118 | I31: 1775457458 | J31: GE82TB7695836080100009 | K31: შპს კოსმო, 427736355 | L31: 427736355 | M31: TBCBGE22 | N31: სს "თიბისი ბანკი" | R31: 427736355 | S31: შპს კოსმო, 427736355 | U31: GMB | W31: 19286517728
A32: 46118 | B32: 21.03.2026-31. 03.2026 საკურიერო და საკომისიო INVOICE 6 | C32: შპს ლაიფ სთორი, 438125574, TBCBGE22, GE38TB7826036080100014 | E32: 550.52 | F32: 18574.94 | G32: შემოსავალი | H32: 46118 | I32: 1775461460 | J32: GE38TB7826036080100014 | K32: შპს ლაიფ სთორი, 438125574 | L32: 438125574 | M32: TBCBGE22 | N32: სს "თიბისი ბანკი" | R32: 438125574 | S32: შპს ლაიფ სთორი, 438125574 | U32: GIB | W32: 19287378206
A33: 46118 | B33: საკურიერო მომსახურების ღირებულება | C33: შპს გრინ ლაბ, 405422127, TBCBGE22, GE37TB7517136020100025 | E33: 254.88 | F33: 18829.82 | G33: შემოსავალი | H33: 46118 | I33: 1775466056 | J33: GE37TB7517136020100025 | K33: შპს გრინ ლაბ, 405422127 | L33: 405422127 | M33: TBCBGE22 | N33: სს "თიბისი ბანკი" | R33: 405422127 | S33: შპს გრინ ლაბ, 405422127 | U33: GIB | W33: 19288918676
A34: 46118 | B34: საკურიერო მომსახურების ღირებულება | C34: შპს მაისიდი, 405483481, TBCBGE22, GE75TB7672636020100005 | E34: 107.38 | F34: 18937.2 | G34: შემოსავალი | H34: 46118 | I34: 1775466173 | J34: GE75TB7672636020100005 | K34: შპს მაისიდი, 405483481 | L34: 405483481 | M34: TBCBGE22 | N34: სს "თიბისი ბანკი" | R34: 405483481 | S34: შპს მაისიდი, 405483481 | U34: GMB | W34: 19288942686
A35: 46118 | B35: დელივერი მომსახურება -მიკრო სატვირთოს მომსახურება | C35: შპს ფეიფერართ, 406207769, TBCBGE22, GE58TB7306836080100006 | E35: 64.9 | F35: 19002.1 | G35: შემოსავალი | H35: 46118 | I35: 1775467295 | J35: GE58TB7306836080100006 | K35: შპს ფეიფერართ, 406207769 | L35: 406207769 | M35: TBCBGE22 | N35: სს "თიბისი ბანკი" | R35: 406207769 | S35: შპს ფეიფერართ, 406207769 | U35: GMB | W35: 19289416012
A36: 46118 | B36: მომსახურების ანაზღაურება | C36: ი/მ გიორგი მეტრეველი, TBCBGE22, GE30TB7774936010100044 | D36: 1352 | F36: 17650.1 | G36: გადარიცხვა თანხის გატანა | H36: 46118 | I36: 1775470969 | J36: GE30TB7774936010100044 | K36: ი/მ გიორგი მეტრეველი | L36: 01401103956 | M36: TBCBGE22 | N36: სს "თიბისი ბანკი" | R36: 405357180 | S36: შპს დელივერერს, 405357180 | U36: GIB | W36: 19291274650
A37: 46118 | B37: მომსახურების ანაზღაურება | C37: კვარაცხელია ნინო, BAGAGE22, GE20BG0000000496131200 | D37: 1055 | F37: 16595.1 | G37: გადარიცხვა თანხის გატანა | H37: 46118 | I37: 1775471031 | J37: GE20BG0000000496131200 | K37: კვარაცხელია ნინო | M37: BAGAGE22 | N37: სს "საქართველოს ბანკი" | R37: 405357180 | S37: შპს დელივერერს, 405357180 | U37: GIN | W37: 19291274732
A38: 46118 | B38: გადარიცხვის საკომისიო | C38: საკომისიო შემოსავალი - იურიდიული პირების გარე გადარიცხვები, TBCBGE22, GE97TB0006001030220310 | D38: 5 | F38: 16590.1 | G38: სხვა ხარჯები | H38: 46118 | I38: 1775471031 | J38: GE97TB0006001030220310 | K38: საკომისიო შემოსავალი - იურიდიული პირების გარე გადარიცხვები | M38: TBCBGE22 | N38: ს.ს. თიბისი ბანკი | U38: GIN | W38: 19291274733
A39: 46118 | B39: მომსახურების ანაზღაურება | C39: ოთარ კუპრეიშვილი, TBCBGE22, GE76TB7494745068100005 | D39: 1090 | F39: 15500.1 | G39: გადარიცხვა თანხის გატანა | H39: 46118 | I39: 1775471057 | J39: GE76TB7494745068100005 | K39: ოთარ კუპრეიშვილი | L39: 42401042214 | M39: TBCBGE22 | N39: სს "თიბისი ბანკი" | R39: 405357180 | S39: შპს დელივერერს, 405357180 | U39: GIB | W39: 19291274744
A40: 46118 | B40: მომსახურების ანაზღაურება | C40: ელოიძე რობერტ, BAGAGE22, GE72BG0000000161067238 | D40: 890 | F40: 14610.1 | G40: გადარიცხვა თანხის გატანა | H40: 46118 | I40: 1775471092 | J40: GE72BG0000000161067238 | K40: ელოიძე რობერტ | M40: BAGAGE22 | N40: სს "საქართველოს ბანკი" | R40: 405357180 | S40: შპს დელივერერს, 405357180 | U40: GIN | W40: 19291274748
...

Sheet Sheet1
D4: ი/მ გიორგი მეტრეველი | E4: =SUMIFS('GE90TB7716236080100009-GEL'!D:D,'GE90TB7716236080100009-GEL'!B:B,"მომსახურების ანაზღაურება",'GE90TB7716236080100009-GEL'!K:K,D4) -> 3173.39 | F4: =SUMIFS('GE90TB7716236080100009-GEL'!D:D,'GE90TB7716236080100009-GEL'!B:B,"მომსახურების ანაზღაურება მარტი",'GE90TB7716236080100009-GEL'!K:K,D4) -> 50.01 | G4: =E4+F4 -> 3223.4
D5: კვარაცხელია ნინო | E5: =SUMIFS('GE90TB7716236080100009-GEL'!D:D,'GE90TB7716236080100009-GEL'!B:B,"მომსახურების ანაზღაურება",'GE90TB7716236080100009-GEL'!K:K,D5) -> 1055 | F5: =SUMIFS('GE90TB7716236080100009-GEL'!D:D,'GE90TB7716236080100009-GEL'!B:B,"მომსახურების ანაზღაურება მარტი",'GE90TB7716236080100009-GEL'!K:K,D5) -> 60.8 | G5: =E5+F5 -> 1115.8
D6: ოთარ კუპრეიშვილი | E6: =SUMIFS('GE90TB7716236080100009-GEL'!D:D,'GE90TB7716236080100009-GEL'!B:B,"მომსახურების ანაზღაურება",'GE90TB7716236080100009-GEL'!K:K,D6) -> 4543 | F6: =SUMIFS('GE90TB7716236080100009-GEL'!D:D,'GE90TB7716236080100009-GEL'!B:B,"მომსახურების ანაზღაურება მარტი",'GE90TB7716236080100009-GEL'!K:K,D6) -> 63 | G6: =E6+F6 -> 4606
D7: ელოიძე რობერტ | E7: =SUMIFS('GE90TB7716236080100009-GEL'!D:D,'GE90TB7716236080100009-GEL'!B:B,"მომსახურების ანაზღაურება",'GE90TB7716236080100009-GEL'!K:K,D7) -> 2047 | F7: =SUMIFS('GE90TB7716236080100009-GEL'!D:D,'GE90TB7716236080100009-GEL'!B:B,"მომსახურების ანაზღაურება მარტი",'GE90TB7716236080100009-GEL'!K:K,D7) -> 43.01 | G7: =E7+F7 -> 2090.01
D8: საბა ცაგარეიშვილი | E8: =SUMIFS('GE90TB7716236080100009-GEL'!D:D,'GE90TB7716236080100009-GEL'!B:B,"მომსახურების ანაზღაურება",'GE90TB7716236080100009-GEL'!K:K,D8) -> 5103.13 | F8: =SUMIFS('GE90TB7716236080100009-GEL'!D:D,'GE90TB7716236080100009-GEL'!B:B,"მომსახურების ანაზღაურება მარტი",'GE90TB7716236080100009-GEL'!K:K,D8) -> 41.5 | G8: =E8+F8 -> 5144.63
D9: ბადრი სირაძე | E9: =SUMIFS('GE90TB7716236080100009-GEL'!D:D,'GE90TB7716236080100009-GEL'!B:B,"მომსახურების ანაზღაურება",'GE90TB7716236080100009-GEL'!K:K,D9) -> 774 | F9: =SUMIFS('GE90TB7716236080100009-GEL'!D:D,'GE90TB7716236080100009-GEL'!B:B,"მომსახურების ანაზღაურება მარტი",'GE90TB7716236080100009-GEL'!K:K,D9) -> 57.85 | G9: =E9+F9 -> 831.85
D10: დავით სვირავა | E10: =SUMIFS('GE90TB7716236080100009-GEL'!D:D,'GE90TB7716236080100009-GEL'!B:B,"მომსახურების ანაზღაურება",'GE90TB7716236080100009-GEL'!K:K,D10) -> 4481.85 | F10: =SUMIFS('GE90TB7716236080100009-GEL'!D:D,'GE90TB7716236080100009-GEL'!B:B,"მომსახურების ანაზღაურება მარტი",'GE90TB7716236080100009-GEL'!K:K,D10) -> 32.8 | G10: =E10+F10 -> 4514.65
D11: დავითი საყვარელიძე | E11: =SUMIFS('GE90TB7716236080100009-GEL'!D:D,'GE90TB7716236080100009-GEL'!B:B,"მომსახურების ანაზღაურება",'GE90TB7716236080100009-GEL'!K:K,D11) -> 924 | F11: =SUMIFS('GE90TB7716236080100009-GEL'!D:D,'GE90TB7716236080100009-GEL'!B:B,"მომსახურების ანაზღაურება მარტი",'GE90TB7716236080100009-GEL'!K:K,D11) -> 80.5 | G11: =E11+F11 -> 1004.5
D12: მიხეილ ლომჯარია | E12: =SUMIFS('GE90TB7716236080100009-GEL'!D:D,'GE90TB7716236080100009-GEL'!B:B,"მომსახურების ანაზღაურება",'GE90TB7716236080100009-GEL'!K:K,D12) -> 1514.77 | F12: =SUMIFS('GE90TB7716236080100009-GEL'!D:D,'GE90TB7716236080100009-GEL'!B:B,"მომსახურების ანაზღაურება მარტი",'GE90TB7716236080100009-GEL'!K:K,D12) -> 39.56 | G12: =E12+F12 -> 1554.33
D13: ინდივიდუალური მეწარმე ბობო ქარ | E13: =SUMIFS('GE90TB7716236080100009-GEL'!D:D,'GE90TB7716236080100009-GEL'!B:B,"მომსახურების ანაზღაურება",'GE90TB7716236080100009-GEL'!K:K,D13) -> 0 | F13: =SUMIFS('GE90TB7716236080100009-GEL'!D:D,'GE90TB7716236080100009-GEL'!B:B,"მომსახურების ანაზღაურება მარტი",'GE90TB7716236080100009-GEL'!K:K,D13) -> 7.12 | G13: =E13+F13 -> 7.12
D14: მელაძე გიორგი | E14: =SUMIFS('GE90TB7716236080100009-GEL'!D:D,'GE90TB7716236080100009-GEL'!B:B,"მომსახურების ანაზღაურება",'GE90TB7716236080100009-GEL'!K:K,D14) -> 1024 | F14: =SUMIFS('GE90TB7716236080100009-GEL'!D:D,'GE90TB7716236080100009-GEL'!B:B,"მომსახურების ანაზღაურება მარტი",'GE90TB7716236080100009-GEL'!K:K,D14) -> 89.5 | G14: =E14+F14 -> 1113.5
